Workbook

Sheet Özet
A2: Corteqs · Şehir içerik teslimi
A3: Sevilla · İspanya · CITY-107
A5: İçerik türü | B5: Dosyada | C5: Asgari | D5: Hedef | E5: Asgariye kalan | F5: Hedefe kalan
A6: Pratik yaşam yanıtı | B6: =COUNTA('Yanıtlar'!$A$8:$A$307) | C6: 212 | D6: 240 | E6: =MAX(C6-B6,0) | F6: =MAX(D6-B6,0)
A7: Keşif noktası | B7: =COUNTA('Mekânlar'!$A$8:$A$187) | C7: 92 | D7: 120 | E7: =MAX(C7-B7,0) | F7: =MAX(D7-B7,0)
A8: Mahalle / yerel bölge | B8: =COUNTA('Mahalleler'!$A$8:$A$47) | C8: 12 | D8: 16 | E8: =MAX(C8-B8,0) | F8: =MAX(D8-B8,0)
A9: Yanıt içeren konu | B9: =SUM('Konular'!$H$8:$H$37) | C9: 12 | D9: 12 | E9: =MAX(C9-B9,0) | F9: =MAX(D9-B9,0)
A10: Farklı mekân fotoğrafı | B10: =SUM('Fotoğraflar'!$S$8:$S$607) | C10: 187 | D10: 250 | E10: =MAX(C10-B10,0) | F10: =MAX(D10-B10,0)
A11: Farklı kapak fotoğrafı | B11: =SUM('Fotoğraflar'!$T$8:$T$607) | C11: 6 | D11: 8 | E11: =MAX(C11-B11,0) | F11: =MAX(D11-B11,0)
A12: Rota | B12: =COUNTA('Rotalar'!$A$8:$A$37) | C12: 9 | D12: 12 | E12: =MAX(C12-B12,0) | F12: =MAX(D12-B12,0)
A13: Sözlük terimi | B13: =COUNTA('Sözlük'!$A$8:$A$107) | C13: 48 | D13: 60 | E13: =MAX(C13-B13,0) | F13: =MAX(D13-B13,0)
A14: v7 · Kaynak zinciri: FotoğrafKaynakları. Miktar, onay değildir.
A16: Dosyayı doldurma sırası
A18: 1. Teslimat ve Şehir alanlarını doldurun; şehir kimliğini tüm sayfalarda aynı kullanın.
A19: 2. Kaynaklar ve Konular kaydını açın. Yanıt, mekân ve mahalle satırlarını bu kimliklere bağlayın.
A20: 3. Bağlantılar, Fotoğraflar ve Kanıtlar satırlarını tamamlayın; rota ve sözlük kaynaklarını ekleyin.
A21: 4. Kaynak kontrol tarihini yazın. Çekim tarihi bilinmiyorsa boş bırakın; tarih uydurmayın.
A22: 5. Paketin tamamı insan editör tarafından incelenir; tek paket kararı yönetim ekranında verilir. Excel’de satır satır onay işaretlemek gerekmez.
A25: Sarı alanlar düzenlenebilir. Koyu satırdaki makine sütun adları (7. satır) ve sayfa adları değişmez. Veri 8. satırdan başlar. Kimlik listelerinde ; kullanın; işlem, belge ve durakları hücre içinde ayrı satırlara yazın.
A28: Fotoğraf miktarı dosya SHA-256 özeti ve rolüyle ölçülür; aynı kareye ait türevler ayrıca ayıklanır. Sayımda kullanılabilir eski alanı korunur, insan onayı yerine geçmez. Paket kararı yönetim ekranındadır.
A31: Asgari eşikler: 212 yanıt, 92 mekân, 12 mahalle, 12 konu, 187 farklı mekân fotoğrafı, 6 kapak, 9 rota, 48 terim. Hedefler: 240 / 120 / 16 / 12 / 250 / 8 / 12 / 60. Bu dosya uygulamaya veya veritabanına içerik yayımlamaz.

Sheet Teslimat
A2: Corteqs · Teslimat bilgileri
A3: Türkçe başlığı okuyun; veriyi 8. satırdan yazın. 7. satırdaki alan adını ve sayfa adını değiştirmeyin.
A5: Zorunlu | B5: Zorunlu | C5: Zorunlu | D5: Zorunlu | E5: İsteğe bağlı | F5: Zorunlu | G5: Zorunlu · tarih | H5: Zorunlu | I5: İsteğe bağlı
A6: Şema sürümü | B6: Teslimat kimliği | C6: Şehir kimliği | D6: Hazırlayan | E6: İnceleyen | F6: Dosya kapsamı | G6: Dosya güncelleme tarihi | H6: Editör durumu | I6: Teslim notu
A7: schema_version | B7: delivery_id | C7: city_id | D7: editor | E7: reviewer | F7: scope | G7: updated_on | H7: editorial_status | I7: notes
A8: 1.0 | B8: city-107-v001 | C8: sevilla | D8: Atınç | F8: Tam teslim | G8: 46320 | H8: Taslak | I8: Claude üretimi (city-pack, ülke paketi ES v9 + Endülüs v2); insan onayı yok; açık konular Teslimler\ACIK_KONULAR.txt.

Sheet Şehir
A2: Corteqs · Şehir profili
A3: Türkçe başlığı okuyun; veriyi 8. satırdan yazın. 7. satırdaki alan adını ve sayfa adını değiştirmeyin.
A5: Zorunlu | B5: Zorunlu | C5: Zorunlu | D5: Zorunlu | E5: Zorunlu | F5: Zorunlu | G5: Zorunlu | H5: Zorunlu | I5: Zorunlu | J5: İsteğe bağlı | K5: İsteğe bağlı | L5: Zorunlu | M5: Zorunlu | N5: Zorunlu | O5: Zorunlu | P5: Zorunlu | Q5: Zorunlu · tarih | R5: İsteğe bağlı | S5: Zorunlu | T5: Zorunlu · tarih | U5: Zorunlu | V5: Zorunlu · tarih | W5: Zorunlu | X5: İsteğe bağlı | Y5: İsteğe bağlı | Z5: İsteğe bağlı | AA5: İsteğe bağlı | AB5: İsteğe bağlı | AC5: İsteğe bağlı | AD5: İsteğe bağlı | AE5: İsteğe bağlı | AF5: İsteğe bağlı | AG5: Zorunlu
A6: Şehir kimliği | B6: Şehir adı | C6: Ülke | D6: Ülke kodu | E6: Dünya bölgesi | F6: Coğrafi kapsam | G6: Rehber başlığı | H6: Rehber giriş metni | I6: Para birimi kodu | J6: Para simgesi | K6: Para birimi adı | L6: Yerel dil | M6: Saat dilimi | N6: Enlem | O6: Boylam | P6: Konum kaynağı | Q6: Konum kontrol tarihi | R6: Konum açıklaması | S6: Kapsam kaynağı | T6: Kapsam kontrol tarihi | U6: Katalog sıra numarası | V6: Rehber kontrol tarihi | W6: Öncelik | X6: Diğer adlar | Y6: Yerel ad | Z6: Şehir cümlesi | AA6: Şehir dizini sırası | AB6: Hava tahmini bağlantısı | AC6: Hava veri sağlayıcısı | AD6: Tahmin bağlantı metni | AE6: Ana kapak kimliği | AF6: Editoryal şehir notları | AG6: Editör durumu
A7: city_id | B7: name | C7: country | D7: country_code | E7: region | F7: kind | G7: title | H7: intro | I7: currency | J7: currency_symbol | K7: currency_label | L7: language | M7: timezone | N7: latitude | O7: longitude | P7: coordinate_source_url | Q7: coordinate_checked_on | R7: coordinate_note | S7: source_url | T7: source_checked_on | U7: source_position | V7: reviewed_on | W7: priority | X7: aliases | Y7: locality | Z7: tagline | AA7: directory_order | AB7: forecast_url | AC7: provider_url | AD7: forecast_label | AE7: hero_photo_id | AF7: editorial_notes | AG7: editorial_status
A8: sevilla | B8: Sevilla | C8: İspanya | D8: ES | E8: EU | F8: city | G8: Sevilla'ya taşınma rehberi: oturum, konut, sağlık ve günlük yaşam | H8: Sevilla'da oturum izni ve adres kaydından sağlığa, kiradan ulaşıma kadar ilk adımları resmî kaynaklara dayanarak sade Türkçeyle öğren; flamenko, Semana Santa ve Feria de Abril ile şehrin kendine özgü yaşamını keşfet. | I8: EUR | J8: € | K8: Euro | L8: İspanyolca | M8: Europe/Madrid | N8: 37.405015 | O8: -5.980007 | P8: https://www.naturalearthdata.com/downloads/10m-cultural-vectors/10m-populated-places/ | Q8: 46305 | S8: https://www.internations.org/all-internations-cities/ | T8: 46305 | U8: 107 | V8: 46320 | W8: 3 | X8: Seville | Y8: Endülüs | Z8: Yeni hayatın için sade adımlar | AB8: https://www.aemet.es/es/eltiempo/prediccion/municipios/sevilla-id41091 | AC8: https://www.aemet.es | AD8: AEMET Sevilla hava tahmini | AE8: sevilla:photo:kapak-01 | AG8: Taslak

Sheet Konular
A2: Corteqs · Pratik yaşam konuları
A3: Türkçe başlığı okuyun; veriyi 8. satırdan yazın. 7. satırdaki alan adını ve sayfa adını değiştirmeyin.
A5: Zorunlu | B5: Zorunlu | C5: Zorunlu | D5: Zorunlu | E5: Zorunlu | F5: Zorunlu | G5: Zorunlu | H5: Hesap · değiştirmeyin
A6: Konu kimliği | B6: Şehir kimliği | C6: Konu adres adı | D6: Konu başlığı | E6: Açıklama | F6: Simge anahtarı | G6: Sıra | H6: Yanıt içeren konu (hesap)
A7: topic_id | B7: city_id | C7: slug | D7: title | E7: description | F7: icon | G7: order | H7: used_count
A8: sevilla:planlama | B8: sevilla | C8: planlama | D8: Taşınmadan önce plan | E8: Sevilla'ya gelmeden önce hazırlanacak belgeler, ilk haftanın sırası, yaz sıcağı ve yeni gelenlere resmî destek veren yerler. | F8: book | G8: 1 | H8: =IF(A8="",0,IF(COUNTIFS('Yanıtlar'!$N$8:$N$307,A8)>0,1,0))
A9: sevilla:oturum | B9: sevilla | C9: oturum | D9: Vize, oturum ve çalışma izni | E9: Oturum vizeleri, TIE ve NIE, AB kayıt sertifikası, Sevilla'daki yabancılar ofisi ve polis randevusu, aile birleşimi. | F9: plane | G9: 2 | H9: =IF(A9="",0,IF(COUNTIFS('Yanıtlar'!$N$8:$N$307,A9)>0,1,0))
A10: sevilla:resmi | B10: sevilla | C10: resmi | D10: Kimlik ve resmî işlemler | E10: Sevilla'da nüfus kaydı (empadronamiento), sosyal güvenlik numarası, Cl@ve ve dijital sertifika, belge tercümesi, ehliyet. | F10: shield | G10: 3 | H10: =IF(A10="",0,IF(COUNTIFS('Yanıtlar'!$N$8:$N$307,A10)>0,1,0))
A11: sevilla:ev | B11: sevilla | C11: ev | D11: Ev ve kira | E11: Sevilla'da kiralık ev arama, kira sözleşmesi ve depozito, kiracı hakları, kira yardımları ve ev satın alma. | F11: home | G11: 4 | H11: =IF(A11="",0,IF(COUNTIFS('Yanıtlar'!$N$8:$N$307,A11)>0,1,0))
A12: sevilla:fatura | B12: sevilla | C12: fatura | D12: Elektrik, gaz, su ve internet | E12: Elektrik ve doğalgaz aboneliği, Sevilla'da su (EMASESA) ve çöp, fatura indirimleri, internet ve mobil hat. | F12: bolt | G12: 5 | H12: =IF(A12="",0,IF(COUNTIFS('Yanıtlar'!$N$8:$N$307,A12)>0,1,0))
A13: sevilla:para | B13: sevilla | C13: para | D13: Banka, vergi ve destekler | E13: Banka hesabı, gelir vergisi beyanı, Endülüs bölge vergileri, belediye vergileri ve sosyal yardımlar. | F13: transfer | G13: 6 | H13: =IF(A13="",0,IF(COUNTIFS('Yanıtlar'!$N$8:$N$307,A13)>0,1,0))
A14: sevilla:saglik | B14: sevilla | C14: saglik | D14: Sağlık ve sigorta | E14: Endülüs sağlık kartı, aile hekimi ve sağlık merkezi, Sevilla'daki hastaneler, acil servis, eczane ve aşılar. | F14: heart | G14: 7 | H14: =IF(A14="",0,IF(COUNTIFS('Yanıtlar'!$N$8:$N$307,A14)>0,1,0))
A15: sevilla:is | B15: sevilla | C15: is | D15: İş ve çalışma hakları | E15: İş arama ve SAE kaydı, asgari ücret ve sözleşmeler, işsizlik ödeneği, Sevilla'da iş kurma ve diploma denkliği. | F15: briefcase | G15: 8 | H15: =IF(A15="",0,IF(COUNTIFS('Yanıtlar'!$N$8:$N$307,A15)>0,1,0))
A16: sevilla:aile | B16: sevilla | C16: aile | D16: Aile, okul ve çocuk | E16: Endülüs'te okul kaydı, okul öncesi eğitim, İspanyolca desteği, çocuk yardımları ve doğum kaydı. | F16: family | G16: 9 | H16: =IF(A16="",0,IF(COUNTIFS('Yanıtlar'!$N$8:$N$307,A16)>0,1,0))
A17: sevilla:ulasim | B17: sevilla | C17: ulasim | D17: Ulaşım ve araç | E17: Sevilla metrosu, otobüs ve tramvay, Cercanías treni, bisiklet, ehliyet ve araç, havalimanı ve şehirlerarası yolculuk. | F17: train | G17: 10 | H17: =IF(A17="",0,IF(COUNTIFS('Yanıtlar'!$N$8:$N$307,A17)>0,1,0))
A18: sevilla:gunluk | B18: sevilla | C18: gunluk | D18: Günlük yaşam ve güvenlik | E18: Acil numaralar, çöp ve geri dönüşüm, kütüphaneler, İspanyolca kursları, yaz sıcağı ve yerel bayramlar. | F18: bag | G18: 11 | H18: =IF(A18="",0,IF(COUNTIFS('Yanıtlar'!$N$8:$N$307,A18)>0,1,0))
A19: sevilla:kesif | B19: sevilla | C19: kesif | D19: Keşif, kültür, doğa ve spor | E19: Sevilla'nın anıtları ve müzeleri, flamenko, parklar ve Guadalquivir kıyısı, çocuklarla gezilecek yerler ve spor. | F19: people | G19: 12 | H19: =IF(A19="",0,IF(COUNTIFS('Yanıtlar'!$N$8:$N$307,A19)>0,1,0))
H20: =IF(A20="",0,IF(COUNTIFS('Yanıtlar'!$N$8:$N$307,A20)>0,1,0))
H21: =IF(A21="",0,IF(COUNTIFS('Yanıtlar'!$N$8:$N$307,A21)>0,1,0))
H22: =IF(A22="",0,IF(COUNTIFS('Yanıtlar'!$N$8:$N$307,A22)>0,1,0))
H23: =IF(A23="",0,IF(COUNTIFS('Yanıtlar'!$N$8:$N$307,A23)>0,1,0))
H24: =IF(A24="",0,IF(COUNTIFS('Yanıtlar'!$N$8:$N$307,A24)>0,1,0))
H25: =IF(A25="",0,IF(COUNTIFS('Yanıtlar'!$N$8:$N$307,A25)>0,1,0))
H26: =IF(A26="",0,IF(COUNTIFS('Yanıtlar'!$N$8:$N$307,A26)>0,1,0))
H27: =IF(A27="",0,IF(COUNTIFS('Yanıtlar'!$N$8:$N$307,A27)>0,1,0))
H28: =IF(A28="",0,IF(COUNTIFS('Yanıtlar'!$N$8:$N$307,A28)>0,1,0))
H29: =IF(A29="",0,IF(COUNTIFS('Yanıtlar'!$N$8:$N$307,A29)>0,1,0))
H30: =IF(A30="",0,IF(COUNTIFS('Yanıtlar'!$N$8:$N$307,A30)>0,1,0))
H31: =IF(A31="",0,IF(COUNTIFS('Yanıtlar'!$N$8:$N$307,A31)>0,1,0))
... H37: =IF(A37="",0,IF(COUNTIFS('Yanıtlar'!$N$8:$N$307,A37)>0,1,0))

Sheet Yanıtlar
A2: Corteqs · Pratik yaşam yanıtları
A3: Türkçe başlığı okuyun; veriyi 8. satırdan yazın. 7. satırdaki alan adını ve sayfa adını değiştirmeyin.
A5: Zorunlu | B5: Zorunlu | C5: Zorunlu | D5: Zorunlu | E5: İsteğe bağlı | F5: Zorunlu | G5: İsteğe bağlı | H5: İsteğe bağlı · ; ile | I5: Zorunlu · ; ile | J5: Zorunlu · tarih | K5: Zorunlu | L5: Zorunlu | M5: Zorunlu | N5: Zorunlu | O5: Zorunlu · alt satır | P5: İsteğe bağlı · alt satır | Q5: İsteğe bağlı | R5: İsteğe bağlı | S5: İsteğe bağlı | T5: İsteğe bağlı · JSON
A6: İçerik kimliği | B6: Şehir kimliği | C6: Adres adı | D6: Başlık | E6: Alt başlık | F6: Türkçe kısa yanıt / özet | G6: Arama sözcükleri | H6: Yaşam aşamaları | I6: Kaynak kimlikleri | J6: İçerik kontrol tarihi | K6: Sıra | L6: Öne çıkar | M6: Editör durumu | N6: Konu kimliği | O6: İşlem adımları | P6: Gereken belgeler | Q6: Süre / son tarih | R6: Ücret / maliyet | S6: İstisna ve dikkat notu | T6: Görsel açıklama yapısı (JSON)
A7: entry_id | B7: city_id | C7: slug | D7: title | E7: subtitle | F7: summary | G7: keywords | H7: stages | I7: source_ids | J7: reviewed_on | K7: order | L7: featured | M7: editorial_status | N7: topic_id | O7: steps | P7: documents | Q7: timing | R7: cost | S7: note | T7: visual_json
A8: sevilla:egitim-sistemi-zorunlu-egitim-ve-okul-turleri | B8: sevilla | C8: egitim-sistemi-zorunlu-egitim-ve-okul-turleri | D8: İspanya'da zorunlu eğitim hangi yaşları kapsar, okul türleri nelerdir ve okula kayıt nasıl işler? | E8: Temel eğitim 6–16 yaş arasıdır, kanunda zorunlu ve ücretsizdir; okullar kamu ve özel (bir kısmı sözleşmeli, concertado); kayıt takvimi bölgene göre değişir | F8: Zorunlu temel eğitim (enseñanza básica) 6 ile 16 yaş arasında, toplam on yıllık okullaşmadır; LOE md. 4 onu herkes için zorunlu ve ücretsiz bir eğitim olarak tanımlar. Temel eğitimi ilkokul (educación primaria), zorunlu ortaöğretim (ESO) ve temel düzey meslek eğitimi döngüleri oluşturur; ESO dört sınıftır ve genellikle 12–16 yaşları arasında okunur. 0–6 yaş okul öncesi eğitim (educación infantil) isteğe bağlıdır. Okullar kamu okulları (sahibi bir kamu idaresi olanlar) ve özel okullar olarak ayrılır; devletle sözleşme rejimine alınan özel okullara centro concertado denir; kamu eğitim hizmeti kamu ve concertado okullar aracılığıyla verilir. Kamu ve concertado okullara kabulü eğitim idareleri düzenler; başvuru takvimi ve puanlama bölgene göre değişir. | G8: zorunlu eğitim, eğitim sistemi, okul türleri, escolarización, admisión, centro concertado, ESO, educación infantil | H8: planning;new | I8: sevilla:kaynak:103 | J8: 46319 | K8: 9081 | L8: Hayır | M8: Taslak | N8: sevilla:aile | O8: Çocuğunun yaşına göre etabı belirle: 0–6 yaş okul öncesi eğitim isteğe bağlıdır, 6–16 yaş temel eğitim kanunda zorunlu ve ücretsiz olarak tanımlanır. Okul türünü seç: kamu okulu, özel okul ya da concertado okul; ebeveyn olarak kamu okulunu da, kamu idarelerinin kurmadığı bir okulu da seçme hakkın var. Kamu ya da concertado okul istiyorsan başvuruyu bölgenin eğitim idaresinin düzenlediği kabul (admisión) süreci üzerinden yap; takvim ve puanlama bölgene göre değişir. Yer yetersizse sıralamayı öncelikli ölçütler belirler: okulda kayıtlı kardeşin, evinin ya da ebeveynlerinden birinin iş yerinin okula yakınlığı ve ailenin kişi başı geliri. Kamu okullarında yer yetersizse, okulun kendisine bağlı (adscrito) okullardan gelen öğrenciler öncelik alır; concertado okullarda benzer bir usul uygulanır. | R8: Kanun, temel eğitimi (6–16 yaş) herkes için zorunlu ve ücretsiz olarak tanımlar (LOE md. 4). | S8: Kabulde doğum, ırk veya etnik köken, cinsiyet, din, görüş, engellilik, yaş gibi nedenlerle ayrımcılık yapılamaz. Ebeveynlerinden birinin zorunlu görev değişikliği, ailede sonradan gelişen engellilik ya da toplumsal cinsiyete dayalı şiddet nedeniyle ikamet değişikliği yüzünden taşındıysan, oturduğun ya da çalıştığın bölgeye göre kabulde tercih hakkın vardır. Zorunlu eğitimden sonraki lise düzeyi (educación secundaria postobligatoria) bachillerato ve orta düzey meslek eğitimi (FP grado medio) gibi öğrenimleri kapsar.
A9: sevilla:yabanci-lise-diplomasi-ile-universiteye-giris | B9: sevilla | C9: yabanci-lise-diplomasi-ile-universiteye-giris | D9: İspanya'da yabancı lise diplomasıyla üniversiteye girmek için ne gerekir, hangi diplomalar giriş sınavından ve denklik (homologación) yaptırmaktan muaftır? | E9: Diplomanın eğitim sistemine bağlı: RD 534/2024 md. 6 kapsamındakilerde sınav ve homologación gerekmez; diğerleri için homologación, UNEDasiss ve PCE | F9: Yol diplomanın geldiği eğitim sistemine göre değişir. AB üye devletlerinin ve karşılıklılık esasıyla uluslararası anlaşma yapılmış devletlerin sistemlerinden gelenler (kendi sistemlerinde üniversiteye giriş şartlarını karşılamaları koşuluyla), Avrupa Okulları'nın Avrupa Bakalorya diploması sahipleri ve Uluslararası Bakalorya (IB) diploması sahipleri giriş sınavı (prueba de acceso) olmadan üniversiteye girebilir ve diplomalarının homologación (resmî denklik) işlemini yaptırmak zorunda değildir (RD 534/2024 md. 6); UNEDasiss bu gruptakiler için de, yabancı notları İspanyol ölçeğine çeviren Acreditación UNEDasiss ve Calificación de Acceso'yu şart koşar. UNEDasiss bu yolu 'AB, Avrupa Yükseköğretim Alanı, IB, Avrupa Okulları, Çin ve Kolombiya' başlığı altında verir; saydığı sistemlerin listesi nottadır. UNEDasiss'in 'AB dışı ülkeler' yolunda, yani diğer uluslararası eğitim sistemlerinden gelenler için UNEDasiss'in aradığı şart şudur: İspanyol bachillerato'suna homologación için gereken şartları karşılıyor olmak; devlet üniversitesi için ayrıca Calificación de Acceso ve PCE sınavları gerekir. Özel üniversitelerde kabul sistemi devlet üniversitelerinden farklıdır. | G9: yabancı diploma, üniversiteye giriş, UNEDasiss, PCE, homologación, prueba de acceso, RD 534/2024, Calificación de Acceso | H9: before;planning;new | I9: sevilla:kaynak:104;sevilla:kaynak:105 | J9: 46319 | K9: 9082 | L9: Hayır | M9: Taslak | N9: sevilla:aile | O9: Diplomanın hangi eğitim sistemine ait olduğuna bak: AB üye devleti, karşılıklılık anlaşmalı devlet, Avrupa Okulları ya da Uluslararası Bakalorya (IB) ise RD 534/2024 md. 6'ya göre sınavsız giriş grubundasın ve homologación yaptırman gerekmez; genel lise diplomanda kendi sisteminde üniversiteye giriş şartlarını karşılamış olman gerekir, meslek diplomaları için ek koşul notta yazılıdır. Bu gruptaysan UNEDasiss'ten Acreditación UNEDasiss'i ve notlarını İspanyol ölçeğine çeviren Calificación de Acceso'yu al. Giriş notunu yükseltmek istersen PCE sınavlarına gir (en az 2 ders önerilir) ve/ya da derslerinin tanınmasını (Reconocimiento de asignaturas) iste. UNEDasiss'in 'Otros países fuera de la UE' yolundaysan, yani diplomanın sistemi yukarıdaki 'AB, EHEA, IB, Avrupa Okulları, Çin ve Kolombiya' grubunda sayılmayan diğer uluslararası bir eğitim sistemindense: İspanyol bachillerato'suna homologación için gereken şartları karşılıyor olmalısın; meslek lisesi mezunuysan Técnico Superior unvanına homologación almış olmalısın. Devlet üniversitesi için Calificación de Acceso'ya ek olarak PCE sınavlarına gir (en az 4 ders önerilir); hangi derslere gireceğini üniversitenin kabul kriterleri belirler: bachillerato modalitesi (4 PCE dersi), PCE'yi İspanyol öğrencilerin PAU'su gibi yapılandırmak (en az 4 zorunlu ders, 1 ya da 2 isteğe bağlı ders) ya da dil belgesi. | P9: Acreditación UNEDasiss (Calificación de Acceso ile) PCE sınavları (ülke dışı diploma için devlet üniversitesinde) | S9: UNEDasiss'in 'AB, Avrupa Yükseköğretim Alanı, IB, Avrupa Okulları, Çin ve Kolombiya' grubunda saydığı sistemler: Almanya, Andorra, Avusturya, Uluslararası Bakalorya, Belçika, Bulgaristan, Çekya, Çin, Kıbrıs, Kolombiya, Hırvatistan, Danimarka, Avrupa Okulları, Slovakya, Slovenya, Estonya, Finlandiya, Fransa, Yunanistan, Macaristan, İrlanda, İzlanda, İtalya, Letonya, Lihtenştayn, Litvanya, Lüksemburg, Malta, Norveç, Hollanda, Polonya, Portekiz, Birleşik Krallık, Romanya, İsveç ve İsviçre. Giriş sınavını geçmesi gereken yabancı sistem öğrencileri RD 534/2024'te ayrı bir grup olarak sayılır ve kabulleri LOE'nin ilgili ek maddesini geliştiren yönetmeliğe göre yapılır. UNEDasiss'in 'AB, Avrupa Yükseköğretim Alanı, IB, Avrupa Okulları, Çin ve Kolombiya' grubunda meslek diplomaları için diplomanın Orden EFD/550/2025'te yer alması ya da Eğitim, Meslek Eğitimi ve Spor Bakanlığı'nın olumlu raporunu alması gerekir.
A10: sevilla:ingreso-minimo-vital-ve-cocuk-destegi | B10: sevilla | C10: ingreso-minimo-vital-ve-cocuk-destegi | D10: İspanya'da Ingreso Mínimo Vital ve çocuk yardımı eki (complemento de ayuda para la infancia) kimlere verilir, yabancı için ikamet şartı nedir? | E10: Başvurudan önceki en az 1 yıl yasal ve fiilî ikamet aranır; AB dışı yabancıda oturum izniyle kanıtlanır; 2026 çocuk eki aylık 115, 80,50 ya da 57,50 € | F10: Ingreso Mínimo Vital (IMV, asgari yaşamsal gelir), ekonomik açıdan kırılgan durumdaki kişilere ve birlikte yaşayan birimlere (unidad de convivencia) verilir; yararlanıcılar (bireysel başvuranlar ve birim üyeleri) için başvurudan önceki en az bir yıl boyunca İspanya'da yasal ve fiilî, kesintisiz ikamet şarttır. Gelirin yanında varlık da aranır: oturduğun ev (vivienda habitual) hariç net varlığı bireysel yararlanıcıda 2026'da 26.409,60 € ve üzerinde olanlar ekonomik kırılgan sayılmaz (ayrıntı notta). AB, AEA ya da İsviçre vatandaşı olmayan yabancıda yasal ikamet, oturum izniyle (autorización de residencia, her türü) ya da AB vatandaşı aile üyesi kartıyla kanıtlanır; Türk vatandaşı bu ikinci gruba girer, yani oturum izninle ya da AB vatandaşının aile üyesiysen aile üyesi kartınla kanıtlarsın. Bir yıl şartı doğum, evlat edinme, çocukların aile birleşimi (reagrupación familiar), evlat edinme amaçlı koruma ya da kalıcı aile yanında bakımla birime katılan reşit olmayanlar için, ayrıca insan ticareti ve cinsel sömürü mağdurları ile toplumsal cinsiyete dayalı şiddet mağduru kadınlar için aranmaz. Reşit olmayan çocuğu olan birimler için çocuk eki (complemento de ayuda para la infancia) de vardır; 2026 için tutarı çocuğun 1 Ocak'ta tamamlanmış yaşına göre aylık 115 €, 80,50 € ya da 57,50 €'dur. | G10: ingreso mínimo vital, IMV, complemento de ayuda para la infancia, çocuk yardımı, Seguridad Social, ikamet şartı, aile yardımı | H10: new;settled | I10: sevilla:kaynak:106;sevilla:kaynak:107 | J10: 46319 | K10: 9083 | L10: Hayır | M10: Taslak | N10: sevilla:aile | O10: Birimin (unidad de convivencia) başvurudan önceki en az altı ay kesintisiz oluşmuş olmalı; başvuru sahibi (titular) genel olarak en az 23 yaşında ve hukuki ehliyetli olmalı. Yasal ve fiilî ikametini en az bir yıllık kesintisiz süre için oturum izninle (her türü) ya da AB vatandaşı aile üyesi kartınla, İspanya'daki adresini ise empadronamiento (belediye nüfus kaydı) belgesiyle kanıtla. Kimlik olarak ülkenin kimlik belgesi, yabancı kimlik kartı (TIE) ya da pasaportunu ver; NIE belgelerde yoksa ayrıca ver. Çocukların için libro de familia ya da Registro Civil'in verdiği doğum belgesini ekle. Başvuruyu Seguridad Social'ın elektronik şubesindeki Servicio Ingreso Mínimo Vital üzerinden yap; IMV'yi ve çocuk ekini buradan talep edersin. Bilgi hattı 020'dir. Aynı çocuk için, engeli olmayan ya da engel oranı %33'ün altında olan çocuk başına aile yardımı (asignación económica por hijo o menor a cargo) alıyorsan IMV ile birlikte alamazsın. IMV tutarı aile yardımından yüksekse IMV tanınır ve aile yardımı hakkı sona erer; IMV daha düşükse ve aile yardımını seçersen IMV başvurusu reddedilir. | P10: Kimlik belgesi: ülkenin kimlik belgesi, yabancı kimlik kartı (TIE) ya da pasaport (ve NIE) Oturum izni (yasal ikamet için) Empadronamiento belgesi (belediye nüfus kaydı) Libro de familia ya da Registro Civil doğum belgesi (çocuklar için) | R10: 2026 için çocuk eki, reşit olmayan her çocuk için aylık: 3 yaşından küçük 115 €; 3 yaşından büyük, 6 yaşından küçük 80,50 €; 6 yaşından büyük, 18 yaşından küçük 57,50 € (yaş, ilgili yılın 1 Ocak'ında tamamlanmış yaşa göre). | S10: 2026'da bireysel yararlanıcı için aylık garantili gelir 733,6 €'dur; bir yetişkin ve bir çocuktan ya da iki yetişkinden oluşan birim için 953,68 €'dur. IMV tutarı, garantili gelirle kişinin ya da birimin gelirleri arasındaki farktır ve bu fark aylık 10 € ya da daha fazla olmalıdır. Çocuk eki, önceki yılın hesaba katılan geliri IMV'nin garantili tutarının %300'ünün altında ve net varlığı ilgili sınırların %150'sinin altında olan birimlere tanınır. Varlık sınırı: oturduğun ev (vivienda habitual) hariç net varlığı bireysel yararlanıcıda 2026'da 26.409,60 € ve üzerinde olanlar ekonomik kırılgan sayılmaz; birimlerde sınır, birimin büyüklüğüne ve yapısına göre yükselir (bir yetişkin ve bir çocuk için 36.973,44 €). Bunun yanında, oturduğun ev (vivienda habitual) hariç şirket dışı varlıkların değeri tek yetişkinli birimde 52.819,20 €'yu (bir yetişkin ve bir çocukta 73.946,88 €'yu) aşıyorsa net varlık değerlendirmesinden bağımsız olarak IMV'ye erişilemez. Birim üyelerinden biri faaliyeti sona ermemiş bir ticari şirketin yöneticisiyse (administrador de derecho) de ekonomik kırılgan sayılmazsın. Sayfa 2026 için geçerlidir.
A11: sevilla:mec-burslari-ab-disi-sart-ve-basvuru-donemi | B11: sevilla | C11: mec-burslari-ab-disi-sart-ve-basvuru-donemi | D11: İspanya'da Eğitim Bakanlığı (MEC) üniversite bursuna AB dışı vatandaş olarak başvurabilir miyim, hangi tutarlar verilir? | E11: AB dışı için üniversite bursu şartı: 18 yaşından küçük olmak ya da 31 Aralık 2025'te oturum izni almış olmak; tutarlar gelir eşiğine göre değişir (2026-2027) | F11: Koşullu evet: Bakanlığın üniversite (grado ve máster) bursunda genel şart İspanyol ya da AB üyesi devlet vatandaşı olmaktır; AB vatandaşı değilsen yabancıların hak ve özgürlüklerine ilişkin mevzuat uygulanır ve 18 yaşından küçüksen ya da 31 Aralık 2025 itibarıyla oturum izni (permiso de residencia) almışsan bursa hak kazanabilirsin; yalnız estancia izni (autorización de estancia) yetmez. 2026-2027 çağrısında üniversite bursunun tutarı aile gelirinin hangi eşikte olduğuna göre değişir; eşik değerleri aile biriminin üye sayısına göre belirlenir (örneğin 1 kişilik aile için yıllık 8.843 / 13.898 / 14.818 €, 4 kişilik aile için 22.107 / 38.242 / 40.773 €). Eşik 1'de ve altında: üniversiteye telafi edilen kayıt bursu, en az 1.700 € (gelire göre), öğrenim sırasında ikamet değiştirmen gerekiyorsa 2.700 €, 8 ve üzeri not için 50–125 € ve gelire ile nota göre hesaplanan değişken tutar. Eşik 2'de 1.700 € yoktur: kayıt bursu, değişken tutar, ikamet değişikliği için 2.700 € ve 8 ve üzeri not için 50–125 € verilir. Eşik 3'te kayıt bursu ve 8 ve üzeri not için en çok 125 € verilir; burs hakkı şu durumlarda yoktur: aile geliri eşik 3'ün üstündeyse; sermaye gelirleri ile değer artışı kazançları toplamı 2025'te 1.900 €'yu aşıyorsa; oturduğun ev dışındaki mülklerin katastro değeri çağrıdaki sınırları aşıyorsa; ticari faaliyet ve ortaklık gelirleri 2025'te 172.000 €'yu aşıyorsa. FP, bachillerato ve diğer üniversite dışı öğrenimlerin bursu için başvuru, Bakanlığın elektronik şubesi (sede electrónica) üzerinden yapılır ve süresi 19 Mayıs'ta sona ermiştir. | G11: MEC bursu, beca, becas y ayudas, AB dışı, oturum izni, sede electrónica, Ministerio de Educación, beca de matrícula | H11: planning;new;settled | I11: sevilla:kaynak:108;sevilla:kaynak:109 | J11: 46319 | K11: 9084 | L11: Hayır | M11: Taslak | N11: sevilla:aile | O11: Önce uyruğuna bak: İspanyol ya da AB üyesi devlet vatandaşıysan genel şartı karşılarsın; AB vatandaşı değilsen 18 yaşından küçük olmalı ya da 31 Aralık 2025 itibarıyla oturum izni (permiso de residencia) almış olmalısın. Üniversite bursunda diğer genel şartı da gör: aynı seviyede ya da daha yüksek bir diploman olmamalı. Akademik şartları gör: ilk yıl grado için 60 kredi kaydı ve üniversiteye girişi sağlayan sınavda ya da öğrenimde en az 5 puan; sonraki yıllarda önceki yıl kredilerinin alana göre belirli yüzdesini başarmış olmak gerekir (ayrıntı notta). FP, bachillerato ve diğer üniversite dışı bursların başvurusu Bakanlığın elektronik şubesinden (sede electrónica) yapılır: Cl@ve ya da elektronik sertifikanla ya da şubeye kayıtlı kullanıcı adı ve şifrenle giriş yap, çevrimiçi formu doldur. FP, bachillerato ve diğer üniversite dışı öğrenimlerde başvuru süresi 19 Mayıs'ta sona erdi; form doldurulurken belge istenmez, gerekli verileri bursları yürüten birimler kendileri sorgular. | R11: 2026-2027 çağrısında üniversite bursu bileşenleri (kayıt bursu üniversiteye telafi edilir, hesabına yatmaz). Eşik 1'de ve altında: en az 1.700 €; öğrenim sırasında ikamet değiştirmen gerekiyorsa 2.700 €; 8 ve üzeri not için 50 € – 125 €; ayrıca gelire ve nota göre hesaplanan değişken tutar. Eşik 2: kayıt bursu, değişken tutar, ikamet değişikliği için 2.700 €, 8 ve üzeri not için 50 € – 125 €. Eşik 3: kayıt bursu ve 8 ve üzeri not için en çok 125 €. | S11: Ekonomik şart olarak 2025 yılı aile birimi geliri esas alınır. AB vatandaşıysan ve sen ya da ailen İspanya'da sürekli ikamet etmiyor veya çalıştığını göstermiyorsa yalnız kayıt bedelini alabilirsin. Alana göre sonraki yıl şartı: mühendislik, mimarlık ve fen bilimlerinde önceki yıl kredilerinin en az %65'ini, sağlık bilimlerinde en az %80'ini, sosyal ve hukuk bilimleri, sanat ve beşeri bilimlerde en az %90'ını başarmış olmak gerekir. Tutarlar Real Decreto 179/2026 ile belirlenen 2026-2027 dönemine aittir.
A12: sevilla:endulus-okul-kaydi-basvuru-donemi-ve-gec-gelen-ogrenci | B12: sevilla | C12: endulus-okul-kaydi-basvuru-donemi-ve-gec-gelen-ogrenci | D12: Endülüs'te okul kaydı ne zaman ve nasıl yapılır, eğitim yılı ortasında gelen çocuk nasıl kaydolur? | E12: Genel kural Mart ayı başvurusu ve Secretaría Virtual; yıl ortasında gelen öğrenci için olağanüstü usul (Decreto 21/2020 md. 51) | F12: Genel kural: Endülüs'te kamu ve devlet destekli özel (concertado) okullara başvuru Mart ayında yapılır; 2026/27 için dönem 1-31 Mart (ikisi dahil) olarak açıklanmıştır. Kesin tarihler yıldan yıla değişebilir, başvurmadan önce Junta'nın eğitim portalından güncel dönemi doğrula. Mart başvurusu 2. kademe Educación Infantil (3-5 yaş), Educación Primaria, ESO ve Bachillerato içindir. O yıl kamu ya da concertado bir okulda kayıtlı olup aynı okulda devam edecek öğrenci Mart'ta başvuru vermez. Bir etabın son sınıfında okuyup sonraki etabın ilk sınıfına bağlı (adscrito) olduğu okulda devam edecek öğrenci de Mart'ta başvuru vermez; çoklu bağlantı (adscripción múltiple) durumu bunun dışındadır. Başvuru okula kâğıtla (Anexo III) ya da elektronik olarak Secretaría Virtual üzerinden verilir; her öğrenci için tek başvuru yapılır ve süre dışı başvuru öncelik kaybettirir. Genel usul bittikten sonra gelen öğrenci (incorporación tardía) için olağanüstü usul vardır: başvuru, çocuğun kabul edilmek istendiği okula ya da eğitim idaresinin il organına yapılır; boş yer varsa okul müdürü kabul eder ve kaydı Séneca sistemiyle yapar, boş yer yoksa başvuru il organına gönderilir. İl organı yer gösterirse matrikül, bildirimden sonraki günden başlayarak iki iş günü içinde yapılmalıdır. Genelleştirilmesi zor (difícil generalización) özel kaynaklar gerektiren çocukta, okulda boş yer olsa bile başvuru yalnız okulun bu kaynakları varsa kabul edilir; yoksa başvuru il organına gönderilir ve il organı bu kaynaklara sahip bir okulda yer verir. | G12: okul kaydı, escolarización, admisión, Secretaría Virtual, incorporación tardía, procedimiento extraordinario, Decreto 21/2020, plaza escolar | H12: planning;new;settled | I12: sevilla:kaynak:136;sevilla:kaynak:137 | J12: 46319 | K12: 9101 | L12: Hayır | M12: Taslak | N12: sevilla:aile | O12: Mart ayındaki genel başvuru döneminde tek bir başvuru formu doldur ve çocuğun öncelikle istediğin okulda (prioritario) başvurusunu ver; kâğıt için Anexo III'ü doldur, elektronik için Secretaría Virtual'ı kullan. Çocuk zaten kayıtlı olduğu okulda devam edecekse ya da bağlı (adscrito) okulda sonraki etabın ilk sınıfına geçecekse (çoklu bağlantı hariç) bu başvuru gerekmez. Başvuruda en çok dört yedek (subsidiario) okul yazabilirsin; okulun kayıtlı başvuru kopyasını sakla. Genel usul bittikten sonra geldiysen (taşınma, evlat edinme gibi acil okullaşma ihtiyacında) başvuruyu çocuğun gireceği okula ya da il eğitim organına ver. Okulda boş yer varsa müdür başvuruyu kabul eder ve kaydı Séneca sisteminde yapar; yer yoksa başvuru il organına gider. Çocuk genelleştirilmesi zor özel kaynaklar gerektiriyorsa başvuru yalnız okulun bu kaynakları varsa kabul edilir; yoksa il organı bu kaynaklara sahip bir okulda yer verir. İl organı sana yer gösterirse bildirimi izleyen günden başlayarak iki iş günü içinde atanan okulda matrikül yaptır. | P12: Başvuru formu: kâğıt için Anexo III, elektronik için Secretaría Virtual | Q12: Genel başvuru: Mart ayı (2026/27 için 1-31 Mart, ikisi dahil; kesin tarihler yıldan yıla değişebilir). Yıl ortası olağanüstü usul: genel usul bittikten sonra; il organı yer gösterirse matrikül için iki iş günü. | S12: Mart başvurusu genel kuraldır; her yılın kesin tarihleri değişebileceğinden güncel dönemi başvurmadan önce Junta'nın eğitim portalından doğrula. Yıl ortasındaki başvuru için belirli bir tarih yoktur; usul genel usul bittikten sonra başlar. Genelleştirilmesi zor özel kaynaklar gerektiren çocuk için başvuru yalnız okulun bu kaynakları varsa kabul edilir; yoksa başvuru il organına gönderilir ve il organı bu kaynaklara sahip bir okulda yer verir.
A13: sevilla:sevilla-kres-escuela-infantil-0-3-yas-basvurusu | B13: sevilla | C13: sevilla-kres-escuela-infantil-0-3-yas-basvurusu | D13: Sevilla'da 0-3 yaş kreş (escuela infantil) başvurusu nasıl yapılır, ne zaman? | E13: 16 haftalıktan 3 yaşa kadar; yeni başvuru her yıl Nisan'da, devam edenlerin yer ayırtma başvurusu Mart'ta başlar (2026/27'de 6 Nisan'a kadar sürdü) | F13: Junta de Andalucía'nın escuela infantil (0-3 yaş kreş) kayıtları 16 haftalıktan üç yaşına kadar olan çocuklar içindir; çocuğa bakan kişinin idari ikametinin (vecindad administrativa) Endülüs'te olması gerekir. Kreşe ilk kez girecekse yeni kabul (nueva admisión) başvurusu her yıl Nisan'da, eylülde başlayan eğitim yılı için yapılır; 2026/27 için dönem 1-30 Nisan 2026'ydı. Aynı kreşte devam edecek çocuklar için yer ayırtma (reserva de plaza) başvurusu Mart'ta başlar ve genel kurala göre bir ya da iki hafta açık kalır; 2026/27'de 16 Mart-6 Nisan 2026 arasındaydı, yani Nisan'ın başına kadar sürdü. Başvuru yılında üç yaşını dolduracak çocuk için kreş yeri istenemez. Bu süreç Junta'ya ait kreşler ile aile yardımı programına bağlı kreşler için işler. | G13: kreş, escuela infantil, 0-3 yaş, nueva admisión, reserva de plaza, Junta de Andalucía, Secretaría Virtual, Sevilla kreş başvurusu | H13: planning;new | I13: sevilla:kaynak:248;sevilla:kaynak:250 | J13: 46319 | K13: 900 | L13: Evet | M13: Taslak | N13: sevilla:aile | O13: Çocuğun yaşını ve ikametini kontrol et: 16 haftalık ile üç yaş arasında olmalı ve çocuğa bakan kişinin idari ikameti Endülüs'te olmalı. Çocuk kreşe ilk kez gidecekse Nisan'da yeni kabul başvurusu ver; form kreşlerde, Delegación Territorial'lerde ve Escolarización portalında bulunur. Çocuk bu yıl Junta'ya ait ya da yardım programına bağlı bir kreşe kayıtlıysa ve orada devam edecekse Mart'taki yer ayırtma başvurusunu ver; yeni kabul başvurusu yapma. İstersen başvuruyu Secretaría Virtual üzerinden elektronik ver; bunun için dijital sertifikan olmalı. Sonucu Mayıs'ta kreşin ilan panosunda yayımlanan listelerden izle. | P13: Başvuru formu (kreşlerden, Delegación Territorial'den ya da Escolarización portalından); elektronik başvuruda dijital sertifika | Q13: Yeni kabul: her yıl Nisan (2026/27 için 1-30 Nisan 2026). Yer ayırtma: Mart (2026/27 için 16 Mart-6 Nisan 2026). | S13: Yukarıdaki tarihler 2026/27 eğitim yılı takvimidir; sonraki yıllarda tarihler yeni takvimle yayımlanır, Nisan ayı yeni kabul için her yıl geçerli kuraldır.
A14: sevilla:sevilla-kres-sonuc-matrikul-bekleme-listesi-ve-olaganustu-basvuru | B14: sevilla | C14: sevilla-kres-sonuc-matrikul-bekleme-listesi-ve-olaganustu-basvuru | D14: Sevilla'da kreş başvurusundan sonra neler olur: sonuç, matrikül, bekleme listesi ve yeniden yerleştirme? | E14: Mayıs'ta puan listesi ve sonuç, Haziran'da matrikül; yer çıkmazsa yeniden yerleştirme ve Temmuz'da olağanüstü kabul | F14: Kreş başvurusunun ardından sırasıyla puan listesi, itiraz süresi, sonuç ve matrikül gelir. 2026/27 takviminde geçici puan listesi 7 Mayıs 2026'da yayımlandı, itiraz (alegaciones) süresi 8-21 Mayıs'tı, kabul sonucu 27 Mayıs'ta açıklandı. Kabul edilenlerin matrikülü 1-10 Haziran, bekleme listesindekilerin matrikülü 11-17 Haziran'dı. Kabul edilip matrikül yaptırmayanların başvurusu 18 Haziran'da vazgeçilmiş sayıldı. Yer bulamayanlar 19-25 Haziran'da yeniden yerleştirme (reubicación) isteyebildi; yer verilenler 26-30 Haziran'da matrikül yaptırdı. Olağanüstü kabul usulü (procedimiento extraordinario) 1 Temmuz'dan itibaren işler. | G14: kreş sonucu, matrikül, bekleme listesi, reubicación, renuncia, procedimiento extraordinario, Anexo, escuela infantil | H14: planning;new | I14: sevilla:kaynak:249;sevilla:kaynak:250 | J14: 46319 | K14: 901 | L14: Hayır | M14: Taslak | N14: sevilla:aile | O14: Mayıs'ta geçici puan listesine bak; puana itirazın varsa itiraz süresi içinde başvur (2026/27'de 8-21 Mayıs). Kabul edildiysen matrikülü Haziran başında yaptır (2026/27'de 1-10 Haziran); bekleme listesindeysen matrikül dönemini izle (2026/27'de 11-17 Haziran). Yer istemiyorsan Anexo VII (renuncia) formunu, kreşi değiştirmek istiyorsan Anexo VIII (cambio de centro) formunu, kreşten ayrılırken Anexo VI (baja) formunu kullan. Yer bulamadıysan Anexo IV formuyla yeniden yerleştirme iste (2026/27'de 19-25 Haziran); yer verilirse hemen sonra matrikül yaptır (26-30 Haziran). Hâlâ yer yoksa Temmuz'dan itibaren işleyen olağanüstü kabul için Anexo V formunu doldur. | P14: Anexo IV (yeniden yerleştirme) Anexo V (olağanüstü kabul) Anexo VI (kreşten ayrılma) Anexo VII (vazgeçme) Anexo VIII (kreş değiştirme) | Q14: 2026/27 takvimi: puan listesi 7 Mayıs, itiraz 8-21 Mayıs, sonuç 27 Mayıs, matrikül 1-10 Haziran, bekleme listesi matrikülü 11-17 Haziran, yeniden yerleştirme başvurusu 19-25 Haziran, olağanüstü kabul 1 Temmuz'dan itibaren. | S14: Tarihler 2026/27 eğitim yılı takvimidir; her yıl yeni takvim yayımlanır ve sıra aynı kalır.
A15: sevilla:sevilla-kres-ucret-yardimi-programa-de-ayuda-a-las-familias | B15: sevilla | C15: sevilla-kres-ucret-yardimi-programa-de-ayuda-a-las-familias | D15: Sevilla'da 0-3 yaş kreş için aile yardımı programı (Programa de ayuda a las familias) nasıl istenir? | E15: Junta'nın yıllık programı: yardım her eğitim yılı için ayrıca istenir, 2026/27'de başvuru 7 Nisan-6 Mayıs'tı | F15: Junta de Andalucía, üç yaşından küçük çocukların birinci kademe Educación Infantil merkezlerinde okullaşmasını teşvik etmek için ailelere yönelik bir yardım programı yürütür. Program yıllıktır; yardım her eğitim yılı için ayrıca istenmelidir. 2026/27 için yardım başvuru dönemi 7 Nisan-6 Mayıs 2026'ydı ve kreşte yer ayırtma ya da normal kabul sürecine katılan çocukları kapsıyordu. Programa bağlı (adherido) kreşler, kabul sürecine Junta'ya ait kreşlerle aynı takvimde katılır. | G15: kreş yardımı, Programa de ayuda a las familias, escuela infantil, 0-3 yaş, aile yardımı, Junta de Andalucía | H15: planning;new | I15: sevilla:kaynak:248;sevilla:kaynak:250 | J15: 46319 | K15: 902 | L15: Hayır | M15: Taslak | N15: sevilla:aile | O15: Çocuğun gideceği kreşin Junta'ya ait ya da yardım programına bağlı bir kreş olup olmadığını kreşin kendisinden öğren. Kreş yeri için yer ayırtma ya da normal kabul başvurunu yap. Yardım başvurusunu da aynı eğitim yılı için ayrıca yap; 2026/27'de dönem 7 Nisan-6 Mayıs 2026'ydı. Formu Escolarización portalının 0-3 yaş formlar sayfasından indir. Eğitim yılı değiştiğinde yardım için yeniden başvur. | P15: Yardım başvuru formu (Escolarización portalının 0-3 yaş formlar sayfasında) | Q15: Yıllık; 2026/27 için başvuru 7 Nisan-6 Mayıs 2026. | S15: Yardım her eğitim yılı için yeniden istenir; geçen yılın başvurusu yeni yıla geçmez.
A16: sevilla:sevilla-atal-ispanyolca-bilmeyen-cocuk-icin-okul-destegi | B16: sevilla | C16: sevilla-atal-ispanyolca-bilmeyen-cocuk-icin-okul-destegi | D16: Sevilla'daki devlet okullarında İspanyolca bilmeyen yabancı çocuklar için ATAL desteği nedir? | E16: Okul saatinde, özel öğretmenle verilen İspanyolca programı; ilkokul ve ESO'daki devlet okullarında | F16: ATAL (Aulas Temporales de Adaptación Lingüística, geçici dil uyum sınıfları), İspanyolca bilmeyen yabancı öğrencilere okul saatinde, bu iş için görevli öğretmenlerce verilen bir İspanyolca öğretim programıdır. Programda çocuğun okula ve çevreye uyumu, İspanyolcanın ders dili olarak öğrenilmesi ve köken kültürünün korunması hedeflenir. Endülüs Eğitim Bakanlığı (Consejería de Educación) programı devlet okullarının Educación Primaria ve ESO kademelerinde uygular; ders normalde çocuğun kendi sınıfında yürür, dili anlama ve konuşmada özel zorluk varsa sınıf dışı destek grupları kurulabilir ve çocuk dil artık belirleyici olmadığında sınıfa tam döner. ATAL öğretmeni üç ayda bir (trimestre başına) her çocuk için bireysel bir ilerleme raporu yazar ve sınıf öğretmenine verir. | G16: ATAL, İspanyolca desteği, yabancı öğrenci, Aulas Temporales de Adaptación Lingüística, Endülüs okul, ilkokul, ESO, uyum sınıfı | H16: new;settled | I16: sevilla:kaynak:251;sevilla:kaynak:246 | J16: 46319 | K16: 907 | L16: Hayır | M16: Taslak | N16: sevilla:aile | O16: Çocuğun okula kayıtlı olduğu devlet okulunun yönetimine İspanyolca bilmediğini bildir ve ATAL desteğini sor. Henüz okul belirlemediysen sorularını Sevilla'daki Delegación Territorial de Educación'a 955034200 numarasından ilet. Çocuk destek grubuna alınırsa dersin bir kısmını sınıf dışında İspanyolcayla geçirir; dili yeterince öğrendiğinde sınıfa tam döner. Üç ayda bir hazırlanan ilerleme raporunu sınıf öğretmeninden iste. | Q16: Okul saatinde, öğretim yılı boyunca | S16: Program devlet okullarının Educación Primaria ve ESO kademelerinde uygulanır.
A17: sevilla:sevilla-yenidogan-bebek-nufus-kaydi-registro-civil | B17: sevilla | C17: sevilla-yenidogan-bebek-nufus-kaydi-registro-civil | D17: Sevilla'da doğan bebeğin nüfus kaydı (Registro Civil) nerede ve hangi şartlarla yapılır? | E17: Sevilla'daki Registro Civil exclusivo Nº1; doğumdan 24 saat sonra 8 güne kadar süre, anne-baba evli olup olmamasına göre farklı usul | F17: Sevilla'da bebeğin kaydı Registro Civil exclusivo Nº1 de Sevilla'da yapılır. Bu ofis, Sevilla'da doğan bebekleri ya da Sevilla dışında doğmuş olsa da anne-babası kayıttan en az üç ay önce Sevilla'da empadronado (belediye kaydı) olanları, ya da ikisinin DNI'sinde aynı Sevilla adresi görünenleri kaydeder. Doğum kaydı için süre, doğumdan 24 saat sonra başlar ve 8 gündür; olağanüstü durumlarda 30 güne uzayabilir. Anne-baba evliyse biri ya da yetkilendirdiği kişi gelebilir; ilk çocuksa beyan formunu ikisi de imzalar ve soyadının babanınki mi annenin mi önce geleceğini gözlemler bölümüne yazar. Evli olmayan çiftlerde anne ve baba birlikte gelmek zorundadır. Kaydı yapılan ilk ortak çocuk için evli olmayan çiftlere aile cüzdanı (libro de familia) verilir. | G17: bebek kaydı, doğum kaydı, Registro Civil Sevilla, nüfus kaydı, libro de familia, empadronamiento, cita previa | H17: new;settled | I17: sevilla:kaynak:252;sevilla:kaynak:254 | J17: 46319 | K17: 908 | L17: Evet | M17: Taslak | N17: sevilla:aile | O17: Hastanenin verdiği sarı formu (impreso amarillo) anne-baba olarak ön ve arka yüzüyle doldur. Kayıt yerini belirle: Sevilla'da doğduysa ya da anne-baba kayıttan üç ay önce Sevilla'da empadronado ise ya da ikisinin DNI'sinde aynı Sevilla adresi varsa Sevilla'daki Registro Civil'e başvur. Anne-baba evliyse biri (ya da yetkilendirdiği kişi) gelebilir; ilk çocuksa beyan formunu ikisi de imzalar ve soyadı tercihini gözlemler kısmına yazar. Evli değillerse ikisi birlikte gider. Cita previa (randevu) için Adalet Bakanlığı'nın çevrim içi randevu sayfasını kullan ya da 600 15 80 95 numarasını ara; DNI'n yoksa aynı numaradan hangi kimlikle gelebileceğini sor. Anne boşanmışsa boşanma kararını ya da boşanmanın yazılı olduğu evlilik belgesini götür; baba reşit değilse expedientes bölümünden randevu al; anne reşit değilse velisiyle birlikte gel. | P17: Hastanenin sarı formu (ön ve arka yüz) Anne-babanın DNI'si (DNI'n yoksa kimlik için 600 15 80 95'i ara) Sevilla dışında doğan bebek için anne-babanın empadronamiento belgesi Boşanmış anne için boşanma kararı ya da boşanmanın yazılı olduğu evlilik belgesi | Q17: Doğumdan 24 saat sonra başlar, 8 güne kadar; olağanüstü durumda 30 güne kadar uzayabilir. | S17: Bazı sağlık merkezlerinde kayıt, anne-babanın merkezde imzaladığı resmî formla ve doktor raporunun elektronik gönderilmesiyle yapılır; bu durumda çoğunlukla Registro Civil ofisine gitmek gerekmez.
A18: sevilla:sevilla-dogum-sonrasi-saglik-sosyal-guvenlik-ve-padron-adimlari | B18: sevilla | C18: sevilla-dogum-sonrasi-saglik-sosyal-guvenlik-ve-padron-adimlari | D18: Sevilla'da doğumdan sonra hangi sağlık ve kayıt adımlarını sırayla yapmalısın? | E18: Taburcu belgeleri, lohusa ziyareti, topuk testi, Seguridad Social kaydı, sağlık kartı ve empadronamiento | F18: Doğum her şey yolundaysa 36-48 saat içinde taburcu ile sonuçlanır ve bu sırada anne ile bebeğin hastane çıkış raporu ile doğum belgesi verilir. Sonra sırayla: sağlık merkezinde randevular (lohusa ziyareti doğumdan 5-9 gün sonra ve bebeğin sağlık izlem programı), yaklaşık üçüncü günde topuk testi, Registro Civil kaydı, Seguridad Social'a (INSS) bebeğin kaydı, ardından sağlık kartı (tarjeta sanitaria) ve bebeğin oturduğun yerin belediyesinde padrón kaydı gelir. Hamilelik sırasında cinsel ve üreme sağlığı sorularını 7/24 ücretsiz 900 850 100 hattına sorabilirsin. | G18: doğum sonrası, taburcu, lohusa ziyareti, topuk testi, prueba del talón, Seguridad Social, tarjeta sanitaria, empadronamiento, libro de familia | H18: new | I18: sevilla:kaynak:254;sevilla:kaynak:273 | J18: 46319 | K18: 909 | L18: Hayır | M18: Taslak | N18: sevilla:aile | O18: Taburcu olurken anne ve bebeğin hastane çıkış raporunu ve doğum belgesini (certificado de nacimiento) al. Sağlık merkezinden lohusa ziyareti (doğumdan 5-9 gün sonra) ve bebeğin sağlık izlem programı için randevu iste. Topuk testini (prueba del talón) yaklaşık üçüncü günde yaptır; randevu gerekmez, sağlık merkezinde ya da tatil günlerinde acil birimlerinde yapılır. Bebeği Registro Civil'e kaydettir ve libro de familia'yı al. Bebeği INSS'in CAISS merkezlerinde ya da 'Tu Seguridad Social' sitesinden Seguridad Social'a kaydet; yüz yüze ya da posta yoluyla kayıtta Junta'nın sayfası libro de familia, DNI ve yararlanıcı başvuru formunu sayar; DNI'n yoksa hangi kimlikle başvurabileceğini INSS'in bilgi hattından (91 542 11 76 ya da 901 16 65 65) sor. Seguridad Social kaydından sonra bebek için sağlık kartı iste ve bebeği oturduğun yerin belediyesinde padrón'a yazdır. | P18: Hastane çıkış raporu ve doğum belgesi Libro de familia (ya da güncellenmemişse doğumun tam metin sertifikasıyla birlikte) DNI (yüz yüze ya da posta yoluyla kayıtta; DNI'n yoksa INSS bilgi hattını ara: 91 542 11 76 ya da 901 16 65 65) Seguridad Social yararlanıcı başvuru formu | Q18: Taburcu: normalde 36-48 saat; lohusa ziyareti 5.-9. gün; topuk testi yaklaşık 3. gün. | S18: Seguridad Social'a elektronik kayıt Tu Seguridad Social sitesinden yapılır.
A19: sevilla:sevilla-registro-civil-hangi-islem-icin-hangi-telefon | B19: sevilla | C19: sevilla-registro-civil-hangi-islem-icin-hangi-telefon | D19: Sevilla Registro Civil'de doğum belgesi, evlilik, babalık tanıma ve diğer işlemler için hangi numara aranır? | E19: İşleme göre ayrı telefon hatları ve babalık tanıma (reconocimiento de paternidad) için gerekenler | F19: Sevilla'daki Registro Civil exclusivo Nº1'in her işlem için ayrı bir telefon hattı var. Genel bilgi için 600 15 80 95 ya da 955 51 00 56; doğum, evlilik ve ölüm sertifikaları için 600 15 80 84; yeni doğan kaydı için 600 15 80 95; dinî nikâh için 600 15 80 91 ya da 955 51 00 39; medeni nikâh için 955 51 00 40; ölüm kaydı için 600 15 80 93; tanıma, soyadı sırası değişikliği gibi kenar not işlemleri için 600 15 80 92; vatandaşlık, hata düzeltme, ad-soyad değişikliği ve gecikmiş doğum kaydı gibi işlemler için 600 15 80 85 ya da 600 15 80 88. Sevilla Registro Civil sayfasına göre babalık tanıma için iki ebeveyn DNI'siyle birlikte gelir; DNI'n yoksa tanıma işlemlerinin hattı 600 15 80 92'den hangi kimlikle gelebileceğini sor. Baba Sevilla'da oturuyor olmalı ve tanınan kişinin doğum sertifikası (certificado literal de nacimiento) gerekir. | G19: Registro Civil Sevilla, telefon, doğum sertifikası, medeni nikâh, babalık tanıma, reconocimiento de paternidad, certificado literal, cita previa | H19: new;settled | I19: sevilla:kaynak:252;sevilla:kaynak:253 | J19: 46319 | K19: 910 | L19: Hayır | M19: Taslak | N19: sevilla:aile | O19: Yapmak istediğin işlemi yukarıdaki hatlardan uygun olana bağla; genel soru için 955 51 00 56 numarasını ya da registrocivil.sevilla@justicia.es adresini kullan. Medeni nikâh için registro.SE.matrimonio.jus@juntadeandalucia.es adresine yaz ya da 955 51 00 40 numarasını ara; belgeleri topla, cita previa al, çift ve bir tanıkla görüş ve törende iki tanık getir. Babalık tanıma için anne ve baba DNI'leriyle birlikte gelinir; DNI'n yoksa 600 15 80 92'yi arayıp hangi kimlikle gelebileceğini sor. Baba Sevilla'da oturuyorsa ve padrón kaydı sunuyorsa işlem Sevilla'da yapılır. Tanınan kişi 12 yaşından büyükse o da gelmelidir; reşitse tanınan gelir, anne gelmez. Randevuyu Adalet Bakanlığı'nın çevrim içi cita previa sayfasından al. | P19: Babalık tanıma için: iki ebeveynin DNI'si (DNI'n yoksa 600 15 80 92'yi ara), babanın padrón kaydı, tanınan kişinin certificado literal de nacimiento'su
A20: sevilla:sevilla-aile-destekleri-ekonomik-yardim-bulusma-noktasi-arabuluculuk | B20: sevilla | C20: sevilla-aile-destekleri-ekonomik-yardim-bulusma-noktasi-arabuluculuk | D20: Endülüs'te ve Sevilla'da çocuklu ailelere hangi sosyal destekler var: ekonomik yardım, buluşma noktası, arabuluculuk? | E20: Ayudas económicas familiares yalnız sosyal hizmetlerin önerisiyle başlar; Punto de Encuentro Familiar ve aile arabuluculuğu | F20: Junta'nın aile desteklerinin ilki ayudas económicas familiares'dir: bakmakla yükümlü olduğu çocukların temel ihtiyaçlarını karşılayacak kaynağı olmayan ailelere verilen geçici, nakdî ya da ayni yardımdır. Yardım süreci aile adına değil, toplum sosyal hizmetleri ekiplerinin (servicios sociales comunitarios) tespiti ve önerisiyle başlar; çocuk 18 yaşına gelince yardım sona erer. Bunun yanında acil durumlar için Ayudas de Emergencia Social vardır. Boşanma ya da ayrılık sırasında çocuğun anne-babasıyla görüşmesi güç oluyorsa ücretsiz ve geçici bir tarafsız mekân olan Punto de Encuentro Familiar kullanılabilir. Ailevi çatışmalar için Registro de Mediación Familiar'daki arabuluculardan yararlanılabilir; koşulları sağlayanlar için nöbetçi (turno de oficio) ücretsiz arabuluculuk vardır. | G20: aile yardımı, ayudas económicas familiares, servicios sociales, Punto de Encuentro Familiar, mediación familiar, Ayuda de Emergencia Social, Junta de Andalucía | H20: settled | I20: sevilla:kaynak:255;sevilla:kaynak:254 | J20: 46319 | K20: 911 | L20: Hayır | M20: Taslak | N20: sevilla:aile | O20: Çocuklarının temel ihtiyaçlarını karşılayamıyorsan oturduğun yerin toplum sosyal hizmetleri (servicios sociales comunitarios) merkezine git; ekonomik yardım süreci bu ekiplerin önerisiyle başlar. Acil ve olağanüstü bir ihtiyacın varsa aynı merkezde Ayuda de Emergencia Social'i sor. Ayrılık ya da boşanma sürecinde çocuğun diğer ebeveynle görüşmesi zorlaşıyorsa Punto de Encuentro Familiar hizmetini iste. Aile içi anlaşmazlıkta arabuluculuk istiyorsan Registro de Mediación Familiar'daki arabulucuları kullan; ücretsizlik koşulunu sağlıyorsan turno de oficio'yu sor. Genel sorular için Junta'nın 012 ya da 955 012 012 hattını ara. | R20: Punto de Encuentro Familiar hizmeti ücretsizdir. | S20: Ekonomik yardım koşullarla gelir: yardımı alan aile, sosyal hizmetlerin öngördüğü tamamlayıcı müdahaleyi kabul etmek zorundadır.
A21: sevilla:sevilla-egitim-delegasyonu-delegacion-territorial-adres-telefon | B21: sevilla | C21: sevilla-egitim-delegasyonu-delegacion-territorial-adres-telefon | D21: Sevilla'da Eğitim Bölge Müdürlüğü (Delegación Territorial de Educación) nerede, nasıl ulaşılır? | E21: Ronda de Tamarguillo adresi, doğrudan telefon ve okul kayıtları için ücretsiz bilgi hattı | F21: Junta de Andalucía'nın Sevilla ilindeki eğitim birimi Delegación Territorial de Educación en Sevilla'dır; Edificio Antiguo Matadero, Ronda de Tamarguillo s/n, Sevilla 41005 adresinde bulunur. Telefonu 955034200, e-postası informacion.dpse.ced@juntadeandalucia.es. Birimin servisleri arasında Servicio de Planificación y Escolarización (okullaşma planlaması), Servicio de Ordenación Educativa ve Servicio de Inspección Educativa vardır. Okullaşma sürecine dair soruları için Consejería'nın ayrı, ücretsiz bir hattı bulunur: 900 848 000, kesintisiz 8.00-19.00. | G21: Delegación de Educación Sevilla, eğitim müdürlüğü, Ronda de Tamarguillo, 955034200, 900 848 000, okullaşma | H21: planning;new;settled | I21: sevilla:kaynak:246;sevilla:kaynak:256 | J21: 46319 | K21: 912 | L21: Hayır | M21: Taslak | N21: sevilla:aile | O21: Yüz yüze gitmek istersen Ronda de Tamarguillo s/n adresindeki Edificio Antiguo Matadero'ya git. Telefonla ulaşmak için 955034200'ü ara; yazılı soru için informacion.dpse.ced@juntadeandalucia.es adresine yaz. Okul kaydı ve yerleştirme sorularında ücretsiz 900 848 000 hattını 8.00-19.00 arasında ara. Okullaşma konusunu sorarken Servicio de Planificación y Escolarización adını an. | Q21: 900 848 000 hattı 8.00-19.00 arasında kesintisiz. | R21: Bilgi hattı ücretsizdir.
A22: sevilla:sevilla-okul-basvurusu-ve-matrikul-online-secretaria-virtual-iande | B22: sevilla | C22: sevilla-okul-basvurusu-ve-matrikul-online-secretaria-virtual-iande | D22: Sevilla'da okul başvurusu ve matrikülü internetten nasıl yaparım: Secretaría Virtual, iANDE, iPASEN? | E22: Okula gitmeden başvuru ve matrikül; iANDE anahtarı iPASEN'de, ders ve yemek formları aynı işlemde | F22: Endülüs'te kamu ve devlet destekli okullara başvuru ve matrikül Secretaría Virtual üzerinden elektronik yapılabilir; böylece iş saatinde okula gitmek gerekmez. Kimlik doğrulaması için üç yol var: iANDE anahtarı, dijital sertifika ve Cl@ve. iANDE anahtarını iPASEN uygulamasındaki Administrador PASEN mesajında bulursun; her çocuk için ayrı anahtar verilir. Yeni anahtar gerekiyorsa herhangi bir okula yüz yüze gitmen gerekir. Online matrikülde ders seçimi yapılır, comedor escolar, aula matinal ve extraescolar formları doldurulur ve görüntü kullanım izni verilir. Matrikül istersen okulda yüz yüze de yapılabilir. Kamu okullarının ve concertado okulların concertada olan kademelerinin 3-5 yaş (Infantil ikinci kademe) kabul süreci tüm Endülüs için aynıdır; concertado okulların concertada olmayan kademeleri farklı olabilir, concertado olmayan özel okullar ise kendi tarih ve koşullarını belirler. Bunları o okuldan öğren. | G22: Secretaría Virtual, iANDE, iPASEN, Cl@ve, online okul kaydı, matrikül, iEscolariza, Endülüs okul başvurusu, escolarización | H22: planning;new | I22: sevilla:kaynak:256;sevilla:kaynak:257 | J22: 46319 | K22: 903 | L22: Hayır | M22: Taslak | N22: sevilla:aile | O22: iPASEN uygulamasını güncelle; mesajlarında Administrador PASEN'den gelen iANDE iletisini bul. İletide her çocuğun anahtarı yazılıdır. iANDE anahtarın yoksa ya da yenisi gerekiyorsa herhangi bir okula yüz yüze git ve iste; dijital sertifika ya da Cl@ve de kullanılabilir. Secretaría Virtual takviminde Solicitudes bölümünden ilgili işlemin bağlantısını aç; bağlantı yalnız ilgili dönem açıkken çalışır. Online matrikülde ders seçimini yap, comedor, aula matinal ve extraescolar formlarını doldur ve görüntü kullanım iznini ver. Okulda yüz yüze yapmak istersen Educación'ın yayımladığı matrikül formlarını indir ve okula götür. Okul ve adres puanı sorgulamak için iEscolariza uygulamasını kullan; kayıt sorularında 900 848 000 numarasını ara. | P22: iANDE anahtarı (iPASEN'den) ya da dijital sertifika ya da Cl@ve Yüz yüze matrikülde: Educación'ın matrikül formu | Q22: Hat 8.00-19.00 arasında kesintisiz; başvuru ve matrikül bağlantıları ilgili dönem açıkken çalışır. | S22: Concertado okulların concertada olmayan kademelerinde ve concertado olmayan özel okullarda başvuru tarihlerini ve koşullarını okulun kendisi belirler.
A23: sevilla:sevilla-okul-yeri-yetersizse-puanlama-ve-oncelik-kriterleri | B23: sevilla | C23: sevilla-okul-yeri-yetersizse-puanlama-ve-oncelik-kriterleri | D23: Sevilla'da okulda yer yetersizse başvurular nasıl puanlanır: kardeş, yakınlık, engel, gelir ve öncelik hakları? | E23: Endülüs kabul ölçütleri: kardeş 14 puan, engel 2-4 puan, gelir yalnız izin verirsen; bağlı okul ve zorunlu taşınma önceliklidir | F23: Bir okulda başvuru sayısı yer sayısını aşarsa kabul şu ölçütlerle sıralanır: okulda kayıtlı kardeş, evin ya da veli iş yerinin yakınlığı, çocukta/ebeveynde/kardeşte engel, ailenin kişi başı yıllık geliri, kalabalık (numerosa) ve tek ebeveynli aile, velilerin çalışması, birinci kademe Educación Infantil'e kayıtlı olma, tek kardeşi olma ve çoğul doğum; Bachillerato'da ayrıca not ortalaması da sayılır. Kardeşler farklı sınıflar için aynı okula başvurursa biri kabul edilince diğerlerine 14 puan verilir (birikmez); aynı sınıfa başvuru varsa biri kabul edilince diğerleri de kabul edilir. Çocukta %33 ile %66 arası engel 3 puan, %66 ve üstü 4 puandır; gelişim bozukluğu da 3 puan sayılır ama yalnız Infantil ikinci kademe (3-5 yaş) başvurularında; velide %33-66 arası 2, %66 ve üstü 3 puan; her engelli kardeş yarım puan (en çok 2). Bağlı (adscrito) okuldan gelenler, velisi o okulda haftada en az 10 saat çalışanlar ve zorunlu iş taşınması gibi nedenlerle gelen aileler öncelik alır. | G23: baremo, puanlama, okul kabul ölçütleri, kardeş puanı, familia numerosa, adscrito, prioridad, Decreto 21/2020, escolarización | H23: planning;new | I23: sevilla:kaynak:136 | J23: 46319 | K23: 904 | L23: Hayır | M23: Taslak | N23: sevilla:aile | O23: Kardeşin başvurduğun okulda kayıtlıysa bunu başvuruda belirt; farklı sınıf için 14 puan alırsın. Adresi mi yoksa velinin iş yerini mi esas alacağını başvuruda seç; çoğu bilgiyi idare kendi kayıtlarından alır, itiraz edersen belgeleri sen sunarsın. Gelir puanını istiyorsan Vergi İdaresi'nin (AEAT) gelir bilgisini vermesine yazılı izin ver; istemiyorsan izin vermeyebilirsin. Çalışma puanı için bakım sorumluluğu olan tüm velilerin, başvuru döneminin başlangıç tarihinden önceki en az altı ay kesintisiz ve haftada en az 20 saat çalışıyor olması gerekir. Kalabalık aile belgen (familia numerosa) süresi dolmuşsa yenileme başvurusunu yap ve kabul kararı çıkmadan önce belgeyi ilet. Başvuruda en çok dört yedek okul yaz; her okulun puanını kamu okulunda okul konseyi, concertado okulda okulun sahibi (titular) hesaplar. | P23: Gerekirse: yürürlükte familia numerosa belgesi Libro de familia (tek ebeveynli aile ya da çoğul doğum için onaylı kopya) Empadronamiento belgesi (adres bilgisi tutmuyorsa) | S23: Bu ölçütler yer yetersiz olduğunda sıralama içindir; yer yeterliyse başvuru doğrudan kabul edilir. Altı aylık çalışma koşulu ve 20 saat sınırı yalnız çalışma puanı içindir.
